<?xml version="1.0" encoding="utf-8"?><testsuites><testsuite name="pytest" errors="1" failures="0" skipped="0" tests="1" time="0.424" timestamp="2024-04-20T21:48:49.399324" hostname="LAPTOP-7SLA5RIG"><testcase classname="pytest" name="internal" time="0.000"><error message="internal error">Traceback (most recent call last):
  File "C:\Users\SHAIK KHAJA MOHIDDIN\AppData\Local\Programs\Python\Python312\Lib\site-packages\_pytest\main.py", line 285, in wrap_session
    session.exitstatus = doit(config, session) or 0
                         ^^^^^^^^^^^^^^^^^^^^^
  File "C:\Users\SHAIK KHAJA MOHIDDIN\AppData\Local\Programs\Python\Python312\Lib\site-packages\_pytest\main.py", line 339, in _main
    config.hook.pytest_runtestloop(session=session)
  File "C:\Users\SHAIK KHAJA MOHIDDIN\AppData\Local\Programs\Python\Python312\Lib\site-packages\pluggy\_hooks.py", line 501, in __call__
    return self._hookexec(self.name, self._hookimpls.copy(), kwargs, firstresult)
           ^^^^^^^^^^^^^^^^^^^^^^^^^^^^^^^^^^^^^^^^^^^^^^^^^^^^^^^^^^^^^^^^^^^^^^
  File "C:\Users\SHAIK KHAJA MOHIDDIN\AppData\Local\Programs\Python\Python312\Lib\site-packages\pluggy\_manager.py", line 119, in _hookexec
    return self._inner_hookexec(hook_name, methods, kwargs, firstresult)
           ^^^^^^^^^^^^^^^^^^^^^^^^^^^^^^^^^^^^^^^^^^^^^^^^^^^^^^^^^^^^^
  File "C:\Users\SHAIK KHAJA MOHIDDIN\AppData\Local\Programs\Python\Python312\Lib\site-packages\pluggy\_callers.py", line 138, in _multicall
    raise exception.with_traceback(exception.__traceback__)
  File "C:\Users\SHAIK KHAJA MOHIDDIN\AppData\Local\Programs\Python\Python312\Lib\site-packages\pluggy\_callers.py", line 121, in _multicall
    teardown.throw(exception)  # type: ignore[union-attr]
    ^^^^^^^^^^^^^^^^^^^^^^^^^
  File "C:\Users\SHAIK KHAJA MOHIDDIN\AppData\Local\Programs\Python\Python312\Lib\site-packages\_pytest\logging.py", line 806, in pytest_runtestloop
    return (yield)  # Run all the tests.
            ^^^^^
  File "C:\Users\SHAIK KHAJA MOHIDDIN\AppData\Local\Programs\Python\Python312\Lib\site-packages\pluggy\_callers.py", line 102, in _multicall
    res = hook_impl.function(*args)
          ^^^^^^^^^^^^^^^^^^^^^^^^^
  File "C:\Users\SHAIK KHAJA MOHIDDIN\AppData\Local\Programs\Python\Python312\Lib\site-packages\_pytest\main.py", line 364, in pytest_runtestloop
    item.config.hook.pytest_runtest_protocol(item=item, nextitem=nextitem)
  File "C:\Users\SHAIK KHAJA MOHIDDIN\AppData\Local\Programs\Python\Python312\Lib\site-packages\pluggy\_hooks.py", line 501, in __call__
    return self._hookexec(self.name, self._hookimpls.copy(), kwargs, firstresult)
           ^^^^^^^^^^^^^^^^^^^^^^^^^^^^^^^^^^^^^^^^^^^^^^^^^^^^^^^^^^^^^^^^^^^^^^
  File "C:\Users\SHAIK KHAJA MOHIDDIN\AppData\Local\Programs\Python\Python312\Lib\site-packages\pluggy\_manager.py", line 119, in _hookexec
    return self._inner_hookexec(hook_name, methods, kwargs, firstresult)
           ^^^^^^^^^^^^^^^^^^^^^^^^^^^^^^^^^^^^^^^^^^^^^^^^^^^^^^^^^^^^^
  File "C:\Users\SHAIK KHAJA MOHIDDIN\AppData\Local\Programs\Python\Python312\Lib\site-packages\pluggy\_callers.py", line 138, in _multicall
    raise exception.with_traceback(exception.__traceback__)
  File "C:\Users\SHAIK KHAJA MOHIDDIN\AppData\Local\Programs\Python\Python312\Lib\site-packages\pluggy\_callers.py", line 121, in _multicall
    teardown.throw(exception)  # type: ignore[union-attr]
    ^^^^^^^^^^^^^^^^^^^^^^^^^
  File "C:\Users\SHAIK KHAJA MOHIDDIN\AppData\Local\Programs\Python\Python312\Lib\site-packages\_pytest\warnings.py", line 111, in pytest_runtest_protocol
    return (yield)
            ^^^^^
  File "C:\Users\SHAIK KHAJA MOHIDDIN\AppData\Local\Programs\Python\Python312\Lib\site-packages\pluggy\_callers.py", line 121, in _multicall
    teardown.throw(exception)  # type: ignore[union-attr]
    ^^^^^^^^^^^^^^^^^^^^^^^^^
  File "C:\Users\SHAIK KHAJA MOHIDDIN\AppData\Local\Programs\Python\Python312\Lib\site-packages\_pytest\assertion\__init__.py", line 175, in pytest_runtest_protocol
    return (yield)
            ^^^^^
  File "C:\Users\SHAIK KHAJA MOHIDDIN\AppData\Local\Programs\Python\Python312\Lib\site-packages\pluggy\_callers.py", line 121, in _multicall
    teardown.throw(exception)  # type: ignore[union-attr]
    ^^^^^^^^^^^^^^^^^^^^^^^^^
  File "C:\Users\SHAIK KHAJA MOHIDDIN\AppData\Local\Programs\Python\Python312\Lib\site-packages\_pytest\unittest.py", line 401, in pytest_runtest_protocol
    res = yield
          ^^^^^
  File "C:\Users\SHAIK KHAJA MOHIDDIN\AppData\Local\Programs\Python\Python312\Lib\site-packages\pluggy\_callers.py", line 121, in _multicall
    teardown.throw(exception)  # type: ignore[union-attr]
    ^^^^^^^^^^^^^^^^^^^^^^^^^
  File "C:\Users\SHAIK KHAJA MOHIDDIN\AppData\Local\Programs\Python\Python312\Lib\site-packages\_pytest\faulthandler.py", line 85, in pytest_runtest_protocol
    return (yield)
            ^^^^^
  File "C:\Users\SHAIK KHAJA MOHIDDIN\AppData\Local\Programs\Python\Python312\Lib\site-packages\pluggy\_callers.py", line 102, in _multicall
    res = hook_impl.function(*args)
          ^^^^^^^^^^^^^^^^^^^^^^^^^
  File "C:\Users\SHAIK KHAJA MOHIDDIN\AppData\Local\Programs\Python\Python312\Lib\site-packages\_pytest\runner.py", line 115, in pytest_runtest_protocol
    runtestprotocol(item, nextitem=nextitem)
  File "C:\Users\SHAIK KHAJA MOHIDDIN\AppData\Local\Programs\Python\Python312\Lib\site-packages\_pytest\runner.py", line 128, in runtestprotocol
    rep = call_and_report(item, "setup", log)
          ^^^^^^^^^^^^^^^^^^^^^^^^^^^^^^^^^^^
  File "C:\Users\SHAIK KHAJA MOHIDDIN\AppData\Local\Programs\Python\Python312\Lib\site-packages\_pytest\runner.py", line 242, in call_and_report
    report: TestReport = ihook.pytest_runtest_makereport(item=item, call=call)
                         ^^^^^^^^^^^^^^^^^^^^^^^^^^^^^^^^^^^^^^^^^^^^^^^^^^^^^
  File "C:\Users\SHAIK KHAJA MOHIDDIN\AppData\Local\Programs\Python\Python312\Lib\site-packages\pluggy\_hooks.py", line 501, in __call__
    return self._hookexec(self.name, self._hookimpls.copy(), kwargs, firstresult)
           ^^^^^^^^^^^^^^^^^^^^^^^^^^^^^^^^^^^^^^^^^^^^^^^^^^^^^^^^^^^^^^^^^^^^^^
  File "C:\Users\SHAIK KHAJA MOHIDDIN\AppData\Local\Programs\Python\Python312\Lib\site-packages\pluggy\_manager.py", line 119, in _hookexec
    return self._inner_hookexec(hook_name, methods, kwargs, firstresult)
           ^^^^^^^^^^^^^^^^^^^^^^^^^^^^^^^^^^^^^^^^^^^^^^^^^^^^^^^^^^^^^
  File "C:\Users\SHAIK KHAJA MOHIDDIN\AppData\Local\Programs\Python\Python312\Lib\site-packages\pluggy\_callers.py", line 155, in _multicall
    teardown[0].send(outcome)
  File "F:\PHYTON&amp;SeleniumByRS\Frameworks\PhytonSelFramework\pythonProject\tests\conftest.py", line 82, in pytest_runtest_makereport
    _capture_screenshot(file_name)
  File "F:\PHYTON&amp;SeleniumByRS\Frameworks\PhytonSelFramework\pythonProject\tests\conftest.py", line 91, in _capture_screenshot
    driver.get_screenshot_as_file(name)
    ^^^^^^^^^^^^^^^^^^^^^^^^^^^^^
AttributeError: 'NoneType' object has no attribute 'get_screenshot_as_file'</error></testcase></testsuite></testsuites>